Workbook

Sheet Transactions
A1: ID | B1: Name | C1: Amount | D1: Type | E1: Created At | F1: Updated At | G1: Description | H1: Account | I1: Category | J1: From Account | K1: To Account | L1: Person | M1: Recurring | N1: User | O1: Account UUID | P1: Category UUID | Q1: From Account UUID | R1: To Account UUID | S1: Person UUID | T1: Recurring UUID | U1: User UUID
A2: 1 | B2: Initial balance | C2: 2000 | D2: Income | E2: 2026-07-04T00:25:08.274 | F2: 2026-07-04T00:25:08.274 | H2: =IF(O2="","",IFERROR(INDEX(Accounts!$B$2:$B$24,MATCH(O2,Accounts!$A$2:$A$24,0)),"Unknown")) | I2: =IF(P2="","",IFERROR(INDEX(Categories!$B$2:$B$25,MATCH(P2,Categories!$A$2:$A$25,0)),"Unknown")) | J2: =IF(Q2="","",IFERROR(INDEX(Accounts!$B$2:$B$24,MATCH(Q2,Accounts!$A$2:$A$24,0)),"Unknown")) | K2: =IF(R2="","",IFERROR(INDEX(Accounts!$B$2:$B$24,MATCH(R2,Accounts!$A$2:$A$24,0)),"Unknown")) | L2: =IF(S2="","",IFERROR(INDEX(People!$B$2:$B$7,MATCH(S2,People!$A$2:$A$7,0)),"Unknown")) | M2: =IF(T2="","",IFERROR(INDEX(Recurrings!$B$2:$B$3,MATCH(T2,Recurrings!$A$2:$A$3,0)),"Unknown")) | N2: =IF(U2="","",IFERROR(INDEX(Users!$B$2:$B$2,MATCH(U2,Users!$A$2:$A$2,0)),"Unknown")) | O2: 07510728-f320-4be7-b92d-39526c02e73d | P2: 1c612037-9067-4e69-aebc-14619b77b363 | U2: 814248de-0f8d-4712-bd00-91d12164a414
A3: 2 | B3: Initial balance | C3: 2000 | D3: Income | E3: 2026-07-01T00:25:36.000 | F3: 2026-07-04T00:28:50.516 | H3: =IF(O3="","",IFERROR(INDEX(Accounts!$B$2:$B$24,MATCH(O3,Accounts!$A$2:$A$24,0)),"Unknown")) | I3: =IF(P3="","",IFERROR(INDEX(Categories!$B$2:$B$25,MATCH(P3,Categories!$A$2:$A$25,0)),"Unknown")) | J3: =IF(Q3="","",IFERROR(INDEX(Accounts!$B$2:$B$24,MATCH(Q3,Accounts!$A$2:$A$24,0)),"Unknown")) | K3: =IF(R3="","",IFERROR(INDEX(Accounts!$B$2:$B$24,MATCH(R3,Accounts!$A$2:$A$24,0)),"Unknown")) | L3: =IF(S3="","",IFERROR(INDEX(People!$B$2:$B$7,MATCH(S3,People!$A$2:$A$7,0)),"Unknown")) | M3: =IF(T3="","",IFERROR(INDEX(Recurrings!$B$2:$B$3,MATCH(T3,Recurrings!$A$2:$A$3,0)),"Unknown")) | N3: =IF(U3="","",IFERROR(INDEX(Users!$B$2:$B$2,MATCH(U3,Users!$A$2:$A$2,0)),"Unknown")) | O3: e4446497-b2a1-4493-a796-44893af13f78 | P3: 1c612037-9067-4e69-aebc-14619b77b363 | U3: 814248de-0f8d-4712-bd00-91d12164a414
A4: 3 | B4: Monthly credit | C4: 4000 | D4: Transfer | E4: 2026-07-01T00:26:51.000 | F4: 2026-07-26T02:46:53.697 | H4: =IF(O4="","",IFERROR(INDEX(Accounts!$B$2:$B$24,MATCH(O4,Accounts!$A$2:$A$24,0)),"Unknown")) | I4: =IF(P4="","",IFERROR(INDEX(Categories!$B$2:$B$25,MATCH(P4,Categories!$A$2:$A$25,0)),"Unknown")) | J4: =IF(Q4="","",IFERROR(INDEX(Accounts!$B$2:$B$24,MATCH(Q4,Accounts!$A$2:$A$24,0)),"Unknown")) | K4: =IF(R4="","",IFERROR(INDEX(Accounts!$B$2:$B$24,MATCH(R4,Accounts!$A$2:$A$24,0)),"Unknown")) | L4: =IF(S4="","",IFERROR(INDEX(People!$B$2:$B$7,MATCH(S4,People!$A$2:$A$7,0)),"Unknown")) | M4: =IF(T4="","",IFERROR(INDEX(Recurrings!$B$2:$B$3,MATCH(T4,Recurrings!$A$2:$A$3,0)),"Unknown")) | N4: =IF(U4="","",IFERROR(INDEX(Users!$B$2:$B$2,MATCH(U4,Users!$A$2:$A$2,0)),"Unknown")) | Q4: 183283c7-9ae3-49e4-ae84-a5364bc337ea | R4: 18110823-8fe5-4547-b1d3-8dbd2cc5b2e3 | S4: 7214a9a0-5619-49f8-8521-181d4faf1190 | U4: 814248de-0f8d-4712-bd00-91d12164a414
A5: 4 | B5: Food | C5: 200 | D5: Expense | E5: 2026-07-04T00:30:18.916 | F5: 2026-07-04T00:30:18.916 | H5: =IF(O5="","",IFERROR(INDEX(Accounts!$B$2:$B$24,MATCH(O5,Accounts!$A$2:$A$24,0)),"Unknown")) | I5: =IF(P5="","",IFERROR(INDEX(Categories!$B$2:$B$25,MATCH(P5,Categories!$A$2:$A$25,0)),"Unknown")) | J5: =IF(Q5="","",IFERROR(INDEX(Accounts!$B$2:$B$24,MATCH(Q5,Accounts!$A$2:$A$24,0)),"Unknown")) | K5: =IF(R5="","",IFERROR(INDEX(Accounts!$B$2:$B$24,MATCH(R5,Accounts!$A$2:$A$24,0)),"Unknown")) | L5: =IF(S5="","",IFERROR(INDEX(People!$B$2:$B$7,MATCH(S5,People!$A$2:$A$7,0)),"Unknown")) | M5: =IF(T5="","",IFERROR(INDEX(Recurrings!$B$2:$B$3,MATCH(T5,Recurrings!$A$2:$A$3,0)),"Unknown")) | N5: =IF(U5="","",IFERROR(INDEX(Users!$B$2:$B$2,MATCH(U5,Users!$A$2:$A$2,0)),"Unknown")) | O5: a5b44f57-40f5-4b0e-96db-1179f20d75d0 | P5: 9ea0a2b1-4b22-40a4-81ab-843452f9c274 | U5: 814248de-0f8d-4712-bd00-91d12164a414
A6: 5 | B6: Daily expenses | C6: 222 | D6: Expense | E6: 2026-07-02T00:30:26.000 | F6: 2026-08-01T02:04:32.575 | H6: =IF(O6="","",IFERROR(INDEX(Accounts!$B$2:$B$24,MATCH(O6,Accounts!$A$2:$A$24,0)),"Unknown")) | I6: =IF(P6="","",IFERROR(INDEX(Categories!$B$2:$B$25,MATCH(P6,Categories!$A$2:$A$25,0)),"Unknown")) | J6: =IF(Q6="","",IFERROR(INDEX(Accounts!$B$2:$B$24,MATCH(Q6,Accounts!$A$2:$A$24,0)),"Unknown")) | K6: =IF(R6="","",IFERROR(INDEX(Accounts!$B$2:$B$24,MATCH(R6,Accounts!$A$2:$A$24,0)),"Unknown")) | L6: =IF(S6="","",IFERROR(INDEX(People!$B$2:$B$7,MATCH(S6,People!$A$2:$A$7,0)),"Unknown")) | M6: =IF(T6="","",IFERROR(INDEX(Recurrings!$B$2:$B$3,MATCH(T6,Recurrings!$A$2:$A$3,0)),"Unknown")) | N6: =IF(U6="","",IFERROR(INDEX(Users!$B$2:$B$2,MATCH(U6,Users!$A$2:$A$2,0)),"Unknown")) | O6: a5b44f57-40f5-4b0e-96db-1179f20d75d0 | P6: b5eb22d9-3779-43fc-99af-eded3ff9bcd8 | U6: 814248de-0f8d-4712-bd00-91d12164a414
A7: 6 | B7: Arbind Saha checkup and meds | C7: 2710 | D7: Expense | E7: 2026-07-02T00:31:29.000 | F7: 2026-07-26T02:49:27.552 | H7: =IF(O7="","",IFERROR(INDEX(Accounts!$B$2:$B$24,MATCH(O7,Accounts!$A$2:$A$24,0)),"Unknown")) | I7: =IF(P7="","",IFERROR(INDEX(Categories!$B$2:$B$25,MATCH(P7,Categories!$A$2:$A$25,0)),"Unknown")) | J7: =IF(Q7="","",IFERROR(INDEX(Accounts!$B$2:$B$24,MATCH(Q7,Accounts!$A$2:$A$24,0)),"Unknown")) | K7: =IF(R7="","",IFERROR(INDEX(Accounts!$B$2:$B$24,MATCH(R7,Accounts!$A$2:$A$24,0)),"Unknown")) | L7: =IF(S7="","",IFERROR(INDEX(People!$B$2:$B$7,MATCH(S7,People!$A$2:$A$7,0)),"Unknown")) | M7: =IF(T7="","",IFERROR(INDEX(Recurrings!$B$2:$B$3,MATCH(T7,Recurrings!$A$2:$A$3,0)),"Unknown")) | N7: =IF(U7="","",IFERROR(INDEX(Users!$B$2:$B$2,MATCH(U7,Users!$A$2:$A$2,0)),"Unknown")) | O7: 183283c7-9ae3-49e4-ae84-a5364bc337ea | P7: 892419eb-083b-410f-b146-1f3c70914aa1 | S7: 7214a9a0-5619-49f8-8521-181d4faf1190 | U7: 814248de-0f8d-4712-bd00-91d12164a414
A8: 7 | B8: Expense | C8: 380 | D8: Expense | E8: 2026-07-03T00:32:26.000 | F8: 2026-07-26T02:49:32.885 | H8: =IF(O8="","",IFERROR(INDEX(Accounts!$B$2:$B$24,MATCH(O8,Accounts!$A$2:$A$24,0)),"Unknown")) | I8: =IF(P8="","",IFERROR(INDEX(Categories!$B$2:$B$25,MATCH(P8,Categories!$A$2:$A$25,0)),"Unknown")) | J8: =IF(Q8="","",IFERROR(INDEX(Accounts!$B$2:$B$24,MATCH(Q8,Accounts!$A$2:$A$24,0)),"Unknown")) | K8: =IF(R8="","",IFERROR(INDEX(Accounts!$B$2:$B$24,MATCH(R8,Accounts!$A$2:$A$24,0)),"Unknown")) | L8: =IF(S8="","",IFERROR(INDEX(People!$B$2:$B$7,MATCH(S8,People!$A$2:$A$7,0)),"Unknown")) | M8: =IF(T8="","",IFERROR(INDEX(Recurrings!$B$2:$B$3,MATCH(T8,Recurrings!$A$2:$A$3,0)),"Unknown")) | N8: =IF(U8="","",IFERROR(INDEX(Users!$B$2:$B$2,MATCH(U8,Users!$A$2:$A$2,0)),"Unknown")) | O8: 183283c7-9ae3-49e4-ae84-a5364bc337ea | P8: 892419eb-083b-410f-b146-1f3c70914aa1 | S8: 7214a9a0-5619-49f8-8521-181d4faf1190 | U8: 814248de-0f8d-4712-bd00-91d12164a414
A9: 8 | B9: Monthly credit | C9: 10000 | D9: Transfer | E9: 2026-07-01T00:34:30.000 | F9: 2026-07-26T02:48:12.466 | H9: =IF(O9="","",IFERROR(INDEX(Accounts!$B$2:$B$24,MATCH(O9,Accounts!$A$2:$A$24,0)),"Unknown")) | I9: =IF(P9="","",IFERROR(INDEX(Categories!$B$2:$B$25,MATCH(P9,Categories!$A$2:$A$25,0)),"Unknown")) | J9: =IF(Q9="","",IFERROR(INDEX(Accounts!$B$2:$B$24,MATCH(Q9,Accounts!$A$2:$A$24,0)),"Unknown")) | K9: =IF(R9="","",IFERROR(INDEX(Accounts!$B$2:$B$24,MATCH(R9,Accounts!$A$2:$A$24,0)),"Unknown")) | L9: =IF(S9="","",IFERROR(INDEX(People!$B$2:$B$7,MATCH(S9,People!$A$2:$A$7,0)),"Unknown")) | M9: =IF(T9="","",IFERROR(INDEX(Recurrings!$B$2:$B$3,MATCH(T9,Recurrings!$A$2:$A$3,0)),"Unknown")) | N9: =IF(U9="","",IFERROR(INDEX(Users!$B$2:$B$2,MATCH(U9,Users!$A$2:$A$2,0)),"Unknown")) | Q9: 183283c7-9ae3-49e4-ae84-a5364bc337ea | R9: 8cedd8c1-7bcb-4b94-be6b-e72b888f1084 | S9: 7214a9a0-5619-49f8-8521-181d4faf1190 | U9: 814248de-0f8d-4712-bd00-91d12164a414
A10: 9 | B10: Arbind Saha checkup and meds | C10: 1250 | D10: Expense | E10: 2026-07-02T00:34:36.000 | F10: 2026-07-26T02:48:24.866 | H10: =IF(O10="","",IFERROR(INDEX(Accounts!$B$2:$B$24,MATCH(O10,Accounts!$A$2:$A$24,0)),"Unknown")) | I10: =IF(P10="","",IFERROR(INDEX(Categories!$B$2:$B$25,MATCH(P10,Categories!$A$2:$A$25,0)),"Unknown")) | J10: =IF(Q10="","",IFERROR(INDEX(Accounts!$B$2:$B$24,MATCH(Q10,Accounts!$A$2:$A$24,0)),"Unknown")) | K10: =IF(R10="","",IFERROR(INDEX(Accounts!$B$2:$B$24,MATCH(R10,Accounts!$A$2:$A$24,0)),"Unknown")) | L10: =IF(S10="","",IFERROR(INDEX(People!$B$2:$B$7,MATCH(S10,People!$A$2:$A$7,0)),"Unknown")) | M10: =IF(T10="","",IFERROR(INDEX(Recurrings!$B$2:$B$3,MATCH(T10,Recurrings!$A$2:$A$3,0)),"Unknown")) | N10: =IF(U10="","",IFERROR(INDEX(Users!$B$2:$B$2,MATCH(U10,Users!$A$2:$A$2,0)),"Unknown")) | O10: 8cedd8c1-7bcb-4b94-be6b-e72b888f1084 | P10: 892419eb-083b-410f-b146-1f3c70914aa1 | S10: 7214a9a0-5619-49f8-8521-181d4faf1190 | U10: 814248de-0f8d-4712-bd00-91d12164a414
A11: 10 | B11: Expense | C11: 80 | D11: Expense | E11: 2026-07-03T00:35:00.000 | F11: 2026-07-26T02:48:30.944 | H11: =IF(O11="","",IFERROR(INDEX(Accounts!$B$2:$B$24,MATCH(O11,Accounts!$A$2:$A$24,0)),"Unknown")) | I11: =IF(P11="","",IFERROR(INDEX(Categories!$B$2:$B$25,MATCH(P11,Categories!$A$2:$A$25,0)),"Unknown")) | J11: =IF(Q11="","",IFERROR(INDEX(Accounts!$B$2:$B$24,MATCH(Q11,Accounts!$A$2:$A$24,0)),"Unknown")) | K11: =IF(R11="","",IFERROR(INDEX(Accounts!$B$2:$B$24,MATCH(R11,Accounts!$A$2:$A$24,0)),"Unknown")) | L11: =IF(S11="","",IFERROR(INDEX(People!$B$2:$B$7,MATCH(S11,People!$A$2:$A$7,0)),"Unknown")) | M11: =IF(T11="","",IFERROR(INDEX(Recurrings!$B$2:$B$3,MATCH(T11,Recurrings!$A$2:$A$3,0)),"Unknown")) | N11: =IF(U11="","",IFERROR(INDEX(Users!$B$2:$B$2,MATCH(U11,Users!$A$2:$A$2,0)),"Unknown")) | O11: 8cedd8c1-7bcb-4b94-be6b-e72b888f1084 | P11: 066d9d96-53ec-4eb7-a045-fc8dfb1d33cb | S11: 7214a9a0-5619-49f8-8521-181d4faf1190 | U11: 814248de-0f8d-4712-bd00-91d12164a414
A12: 11 | B12: Expense | C12: 70 | D12: Expense | E12: 2026-07-01T00:35:48.000 | F12: 2026-07-26T02:47:02.542 | H12: =IF(O12="","",IFERROR(INDEX(Accounts!$B$2:$B$24,MATCH(O12,Accounts!$A$2:$A$24,0)),"Unknown")) | I12: =IF(P12="","",IFERROR(INDEX(Categories!$B$2:$B$25,MATCH(P12,Categories!$A$2:$A$25,0)),"Unknown")) | J12: =IF(Q12="","",IFERROR(INDEX(Accounts!$B$2:$B$24,MATCH(Q12,Accounts!$A$2:$A$24,0)),"Unknown")) | K12: =IF(R12="","",IFERROR(INDEX(Accounts!$B$2:$B$24,MATCH(R12,Accounts!$A$2:$A$24,0)),"Unknown")) | L12: =IF(S12="","",IFERROR(INDEX(People!$B$2:$B$7,MATCH(S12,People!$A$2:$A$7,0)),"Unknown")) | M12: =IF(T12="","",IFERROR(INDEX(Recurrings!$B$2:$B$3,MATCH(T12,Recurrings!$A$2:$A$3,0)),"Unknown")) | N12: =IF(U12="","",IFERROR(INDEX(Users!$B$2:$B$2,MATCH(U12,Users!$A$2:$A$2,0)),"Unknown")) | O12: 18110823-8fe5-4547-b1d3-8dbd2cc5b2e3 | P12: 892419eb-083b-410f-b146-1f3c70914aa1 | S12: ca7539c0-14da-430a-ae59-44fee8b96222 | U12: 814248de-0f8d-4712-bd00-91d12164a414
A13: 12 | B13: Expense | C13: 64 | D13: Expense | E13: 2026-07-02T00:36:16.000 | F13: 2026-07-26T02:47:09.293 | H13: =IF(O13="","",IFERROR(INDEX(Accounts!$B$2:$B$24,MATCH(O13,Accounts!$A$2:$A$24,0)),"Unknown")) | I13: =IF(P13="","",IFERROR(INDEX(Categories!$B$2:$B$25,MATCH(P13,Categories!$A$2:$A$25,0)),"Unknown")) | J13: =IF(Q13="","",IFERROR(INDEX(Accounts!$B$2:$B$24,MATCH(Q13,Accounts!$A$2:$A$24,0)),"Unknown")) | K13: =IF(R13="","",IFERROR(INDEX(Accounts!$B$2:$B$24,MATCH(R13,Accounts!$A$2:$A$24,0)),"Unknown")) | L13: =IF(S13="","",IFERROR(INDEX(People!$B$2:$B$7,MATCH(S13,People!$A$2:$A$7,0)),"Unknown")) | M13: =IF(T13="","",IFERROR(INDEX(Recurrings!$B$2:$B$3,MATCH(T13,Recurrings!$A$2:$A$3,0)),"Unknown")) | N13: =IF(U13="","",IFERROR(INDEX(Users!$B$2:$B$2,MATCH(U13,Users!$A$2:$A$2,0)),"Unknown")) | O13: 18110823-8fe5-4547-b1d3-8dbd2cc5b2e3 | P13: 892419eb-083b-410f-b146-1f3c70914aa1 | S13: ca7539c0-14da-430a-ae59-44fee8b96222 | U13: 814248de-0f8d-4712-bd00-91d12164a414
A14: 13 | B14: Expense | C14: 286 | D14: Expense | E14: 2026-07-03T00:36:34.000 | F14: 2026-07-26T02:47:18.033 | H14: =IF(O14="","",IFERROR(INDEX(Accounts!$B$2:$B$24,MATCH(O14,Accounts!$A$2:$A$24,0)),"Unknown")) | I14: =IF(P14="","",IFERROR(INDEX(Categories!$B$2:$B$25,MATCH(P14,Categories!$A$2:$A$25,0)),"Unknown")) | J14: =IF(Q14="","",IFERROR(INDEX(Accounts!$B$2:$B$24,MATCH(Q14,Accounts!$A$2:$A$24,0)),"Unknown")) | K14: =IF(R14="","",IFERROR(INDEX(Accounts!$B$2:$B$24,MATCH(R14,Accounts!$A$2:$A$24,0)),"Unknown")) | L14: =IF(S14="","",IFERROR(INDEX(People!$B$2:$B$7,MATCH(S14,People!$A$2:$A$7,0)),"Unknown")) | M14: =IF(T14="","",IFERROR(INDEX(Recurrings!$B$2:$B$3,MATCH(T14,Recurrings!$A$2:$A$3,0)),"Unknown")) | N14: =IF(U14="","",IFERROR(INDEX(Users!$B$2:$B$2,MATCH(U14,Users!$A$2:$A$2,0)),"Unknown")) | O14: 18110823-8fe5-4547-b1d3-8dbd2cc5b2e3 | P14: 892419eb-083b-410f-b146-1f3c70914aa1 | S14: ca7539c0-14da-430a-ae59-44fee8b96222 | U14: 814248de-0f8d-4712-bd00-91d12164a414
A15: 14 | B15: Savings | C15: 267280 | D15: Income | E15: 2026-07-04T00:37:57.260 | F15: 2026-07-04T00:37:57.260 | H15: =IF(O15="","",IFERROR(INDEX(Accounts!$B$2:$B$24,MATCH(O15,Accounts!$A$2:$A$24,0)),"Unknown")) | I15: =IF(P15="","",IFERROR(INDEX(Categories!$B$2:$B$25,MATCH(P15,Categories!$A$2:$A$25,0)),"Unknown")) | J15: =IF(Q15="","",IFERROR(INDEX(Accounts!$B$2:$B$24,MATCH(Q15,Accounts!$A$2:$A$24,0)),"Unknown")) | K15: =IF(R15="","",IFERROR(INDEX(Accounts!$B$2:$B$24,MATCH(R15,Accounts!$A$2:$A$24,0)),"Unknown")) | L15: =IF(S15="","",IFERROR(INDEX(People!$B$2:$B$7,MATCH(S15,People!$A$2:$A$7,0)),"Unknown")) | M15: =IF(T15="","",IFERROR(INDEX(Recurrings!$B$2:$B$3,MATCH(T15,Recurrings!$A$2:$A$3,0)),"Unknown")) | N15: =IF(U15="","",IFERROR(INDEX(Users!$B$2:$B$2,MATCH(U15,Users!$A$2:$A$2,0)),"Unknown")) | O15: a5b44f57-40f5-4b0e-96db-1179f20d75d0 | P15: 1c612037-9067-4e69-aebc-14619b77b363 | U15: 814248de-0f8d-4712-bd00-91d12164a414
A16: 15 | B16: Uttam jewellers | C16: 100000 | D16: Expense | E16: 2026-07-03T20:15:58.000 | F16: 2026-07-26T02:49:05.806 | G16: 24 gm gold adv | H16: =IF(O16="","",IFERROR(INDEX(Accounts!$B$2:$B$24,MATCH(O16,Accounts!$A$2:$A$24,0)),"Unknown")) | I16: =IF(P16="","",IFERROR(INDEX(Categories!$B$2:$B$25,MATCH(P16,Categories!$A$2:$A$25,0)),"Unknown")) | J16: =IF(Q16="","",IFERROR(INDEX(Accounts!$B$2:$B$24,MATCH(Q16,Accounts!$A$2:$A$24,0)),"Unknown")) | K16: =IF(R16="","",IFERROR(INDEX(Accounts!$B$2:$B$24,MATCH(R16,Accounts!$A$2:$A$24,0)),"Unknown")) | L16: =IF(S16="","",IFERROR(INDEX(People!$B$2:$B$7,MATCH(S16,People!$A$2:$A$7,0)),"Unknown")) | M16: =IF(T16="","",IFERROR(INDEX(Recurrings!$B$2:$B$3,MATCH(T16,Recurrings!$A$2:$A$3,0)),"Unknown")) | N16: =IF(U16="","",IFERROR(INDEX(Users!$B$2:$B$2,MATCH(U16,Users!$A$2:$A$2,0)),"Unknown")) | O16: 6b8aeda1-8500-4f9c-996c-55ad6f6d1bf3 | P16: d4addfc4-44b5-4628-8237-9afb254f475b | S16: 7214a9a0-5619-49f8-8521-181d4faf1190 | U16: 814248de-0f8d-4712-bd00-91d12164a414
A17: 16 | B17: Deposit | C17: 50000 | D17: Transfer | E17: 2026-07-04T20:17:53.000 | F17: 2026-07-04T20:18:18.933 | H17: =IF(O17="","",IFERROR(INDEX(Accounts!$B$2:$B$24,MATCH(O17,Accounts!$A$2:$A$24,0)),"Unknown")) | I17: =IF(P17="","",IFERROR(INDEX(Categories!$B$2:$B$25,MATCH(P17,Categories!$A$2:$A$25,0)),"Unknown")) | J17: =IF(Q17="","",IFERROR(INDEX(Accounts!$B$2:$B$24,MATCH(Q17,Accounts!$A$2:$A$24,0)),"Unknown")) | K17: =IF(R17="","",IFERROR(INDEX(Accounts!$B$2:$B$24,MATCH(R17,Accounts!$A$2:$A$24,0)),"Unknown")) | L17: =IF(S17="","",IFERROR(INDEX(People!$B$2:$B$7,MATCH(S17,People!$A$2:$A$7,0)),"Unknown")) | M17: =IF(T17="","",IFERROR(INDEX(Recurrings!$B$2:$B$3,MATCH(T17,Recurrings!$A$2:$A$3,0)),"Unknown")) | N17: =IF(U17="","",IFERROR(INDEX(Users!$B$2:$B$2,MATCH(U17,Users!$A$2:$A$2,0)),"Unknown")) | Q17: a5b44f57-40f5-4b0e-96db-1179f20d75d0 | R17: 2b9af0c9-8855-4666-9be1-4c781d9f1ec3 | U17: 814248de-0f8d-4712-bd00-91d12164a414
A18: 17 | B18: Deposit | C18: 11000 | D18: Transfer | E18: 2026-07-04T20:21:25.767 | F18: 2026-07-04T20:21:25.767 | H18: =IF(O18="","",IFERROR(INDEX(Accounts!$B$2:$B$24,MATCH(O18,Accounts!$A$2:$A$24,0)),"Unknown")) | I18: =IF(P18="","",IFERROR(INDEX(Categories!$B$2:$B$25,MATCH(P18,Categories!$A$2:$A$25,0)),"Unknown")) | J18: =IF(Q18="","",IFERROR(INDEX(Accounts!$B$2:$B$24,MATCH(Q18,Accounts!$A$2:$A$24,0)),"Unknown")) | K18: =IF(R18="","",IFERROR(INDEX(Accounts!$B$2:$B$24,MATCH(R18,Accounts!$A$2:$A$24,0)),"Unknown")) | L18: =IF(S18="","",IFERROR(INDEX(People!$B$2:$B$7,MATCH(S18,People!$A$2:$A$7,0)),"Unknown")) | M18: =IF(T18="","",IFERROR(INDEX(Recurrings!$B$2:$B$3,MATCH(T18,Recurrings!$A$2:$A$3,0)),"Unknown")) | N18: =IF(U18="","",IFERROR(INDEX(Users!$B$2:$B$2,MATCH(U18,Users!$A$2:$A$2,0)),"Unknown")) | Q18: 4b9fa03c-eddf-42ff-8d5f-eaa9e3086ce0 | R18: 2b9af0c9-8855-4666-9be1-4c781d9f1ec3 | U18: 814248de-0f8d-4712-bd00-91d12164a414
A19: 18 | B19: Spotify premium | C19: 59 | D19: Expense | E19: 2026-07-01T20:43:00.811 | F19: 2026-07-04T20:44:03.418 | H19: =IF(O19="","",IFERROR(INDEX(Accounts!$B$2:$B$24,MATCH(O19,Accounts!$A$2:$A$24,0)),"Unknown")) | I19: =IF(P19="","",IFERROR(INDEX(Categories!$B$2:$B$25,MATCH(P19,Categories!$A$2:$A$25,0)),"Unknown")) | J19: =IF(Q19="","",IFERROR(INDEX(Accounts!$B$2:$B$24,MATCH(Q19,Accounts!$A$2:$A$24,0)),"Unknown")) | K19: =IF(R19="","",IFERROR(INDEX(Accounts!$B$2:$B$24,MATCH(R19,Accounts!$A$2:$A$24,0)),"Unknown")) | L19: =IF(S19="","",IFERROR(INDEX(People!$B$2:$B$7,MATCH(S19,People!$A$2:$A$7,0)),"Unknown")) | M19: =IF(T19="","",IFERROR(INDEX(Recurrings!$B$2:$B$3,MATCH(T19,Recurrings!$A$2:$A$3,0)),"Unknown")) | N19: =IF(U19="","",IFERROR(INDEX(Users!$B$2:$B$2,MATCH(U19,Users!$A$2:$A$2,0)),"Unknown")) | O19: a5b44f57-40f5-4b0e-96db-1179f20d75d0 | P19: 892419eb-083b-410f-b146-1f3c70914aa1 | T19: c893b300-6371-4ec2-b676-904a53f5443f | U19: 814248de-0f8d-4712-bd00-91d12164a414
A20: 19 | B20: Office Transport Leverage | C20: 200 | D20: Income | E20: 2026-07-02T20:44:45.223 | F20: 2026-07-04T20:48:36.862 | H20: =IF(O20="","",IFERROR(INDEX(Accounts!$B$2:$B$24,MATCH(O20,Accounts!$A$2:$A$24,0)),"Unknown")) | I20: =IF(P20="","",IFERROR(INDEX(Categories!$B$2:$B$25,MATCH(P20,Categories!$A$2:$A$25,0)),"Unknown")) | J20: =IF(Q20="","",IFERROR(INDEX(Accounts!$B$2:$B$24,MATCH(Q20,Accounts!$A$2:$A$24,0)),"Unknown")) | K20: =IF(R20="","",IFERROR(INDEX(Accounts!$B$2:$B$24,MATCH(R20,Accounts!$A$2:$A$24,0)),"Unknown")) | L20: =IF(S20="","",IFERROR(INDEX(People!$B$2:$B$7,MATCH(S20,People!$A$2:$A$7,0)),"Unknown")) | M20: =IF(T20="","",IFERROR(INDEX(Recurrings!$B$2:$B$3,MATCH(T20,Recurrings!$A$2:$A$3,0)),"Unknown")) | N20: =IF(U20="","",IFERROR(INDEX(Users!$B$2:$B$2,MATCH(U20,Users!$A$2:$A$2,0)),"Unknown")) | O20: f89518bd-b7d1-4658-9692-994af79cfcb8 | P20: f894a6a7-dfc4-4c79-bf71-b2526dc474ac | T20: 5f717740-b341-4fec-9dee-eb1c70d3c260 | U20: 814248de-0f8d-4712-bd00-91d12164a414
A21: 22 | B21: Daily office transport perk | C21: 200 | D21: Income | E21: 2026-06-29T20:49:42.000 | F21: 2026-07-04T20:50:19.391 | H21: =IF(O21="","",IFERROR(INDEX(Accounts!$B$2:$B$24,MATCH(O21,Accounts!$A$2:$A$24,0)),"Unknown")) | I21: =IF(P21="","",IFERROR(INDEX(Categories!$B$2:$B$25,MATCH(P21,Categories!$A$2:$A$25,0)),"Unknown")) | J21: =IF(Q21="","",IFERROR(INDEX(Accounts!$B$2:$B$24,MATCH(Q21,Accounts!$A$2:$A$24,0)),"Unknown")) | K21: =IF(R21="","",IFERROR(INDEX(Accounts!$B$2:$B$24,MATCH(R21,Accounts!$A$2:$A$24,0)),"Unknown")) | L21: =IF(S21="","",IFERROR(INDEX(People!$B$2:$B$7,MATCH(S21,People!$A$2:$A$7,0)),"Unknown")) | M21: =IF(T21="","",IFERROR(INDEX(Recurrings!$B$2:$B$3,MATCH(T21,Recurrings!$A$2:$A$3,0)),"Unknown")) | N21: =IF(U21="","",IFERROR(INDEX(Users!$B$2:$B$2,MATCH(U21,Users!$A$2:$A$2,0)),"Unknown")) | O21: f89518bd-b7d1-4658-9692-994af79cfcb8 | P21: f894a6a7-dfc4-4c79-bf71-b2526dc474ac | U21: 814248de-0f8d-4712-bd00-91d12164a414
A22: 23 | B22: Daily office transport perk | C22: 200 | D22: Income | E22: 2026-06-30T20:50:42.000 | F22: 2026-07-04T20:51:07.056 | H22: =IF(O22="","",IFERROR(INDEX(Accounts!$B$2:$B$24,MATCH(O22,Accounts!$A$2:$A$24,0)),"Unknown")) | I22: =IF(P22="","",IFERROR(INDEX(Categories!$B$2:$B$25,MATCH(P22,Categories!$A$2:$A$25,0)),"Unknown")) | J22: =IF(Q22="","",IFERROR(INDEX(Accounts!$B$2:$B$24,MATCH(Q22,Accounts!$A$2:$A$24,0)),"Unknown")) | K22: =IF(R22="","",IFERROR(INDEX(Accounts!$B$2:$B$24,MATCH(R22,Accounts!$A$2:$A$24,0)),"Unknown")) | L22: =IF(S22="","",IFERROR(INDEX(People!$B$2:$B$7,MATCH(S22,People!$A$2:$A$7,0)),"Unknown")) | M22: =IF(T22="","",IFERROR(INDEX(Recurrings!$B$2:$B$3,MATCH(T22,Recurrings!$A$2:$A$3,0)),"Unknown")) | N22: =IF(U22="","",IFERROR(INDEX(Users!$B$2:$B$2,MATCH(U22,Users!$A$2:$A$2,0)),"Unknown")) | O22: f89518bd-b7d1-4658-9692-994af79cfcb8 | P22: f894a6a7-dfc4-4c79-bf71-b2526dc474ac | U22: 814248de-0f8d-4712-bd00-91d12164a414
A23: 24 | B23: Snacks | C23: 130 | D23: Income | E23: 2026-07-02T20:53:32.000 | F23: 2026-07-17T14:47:22.810 | G23: Paid on 6th july | H23: =IF(O23="","",IFERROR(INDEX(Accounts!$B$2:$B$24,MATCH(O23,Accounts!$A$2:$A$24,0)),"Unknown")) | I23: =IF(P23="","",IFERROR(INDEX(Categories!$B$2:$B$25,MATCH(P23,Categories!$A$2:$A$25,0)),"Unknown")) | J23: =IF(Q23="","",IFERROR(INDEX(Accounts!$B$2:$B$24,MATCH(Q23,Accounts!$A$2:$A$24,0)),"Unknown")) | K23: =IF(R23="","",IFERROR(INDEX(Accounts!$B$2:$B$24,MATCH(R23,Accounts!$A$2:$A$24,0)),"Unknown")) | L23: =IF(S23="","",IFERROR(INDEX(People!$B$2:$B$7,MATCH(S23,People!$A$2:$A$7,0)),"Unknown")) | M23: =IF(T23="","",IFERROR(INDEX(Recurrings!$B$2:$B$3,MATCH(T23,Recurrings!$A$2:$A$3,0)),"Unknown")) | N23: =IF(U23="","",IFERROR(INDEX(Users!$B$2:$B$2,MATCH(U23,Users!$A$2:$A$2,0)),"Unknown")) | O23: 7aeb233a-f5a8-4242-9a4a-0b401a7cf99b | P23: e437a0b5-5f69-4f5b-b879-b8de520215cc | U23: 814248de-0f8d-4712-bd00-91d12164a414
A24: 25 | B24: Expense | C24: 122 | D24: Expense | E24: 2026-07-04T23:05:11.900 | F24: 2026-07-26T02:47:24.733 | H24: =IF(O24="","",IFERROR(INDEX(Accounts!$B$2:$B$24,MATCH(O24,Accounts!$A$2:$A$24,0)),"Unknown")) | I24: =IF(P24="","",IFERROR(INDEX(Categories!$B$2:$B$25,MATCH(P24,Categories!$A$2:$A$25,0)),"Unknown")) | J24: =IF(Q24="","",IFERROR(INDEX(Accounts!$B$2:$B$24,MATCH(Q24,Accounts!$A$2:$A$24,0)),"Unknown")) | K24: =IF(R24="","",IFERROR(INDEX(Accounts!$B$2:$B$24,MATCH(R24,Accounts!$A$2:$A$24,0)),"Unknown")) | L24: =IF(S24="","",IFERROR(INDEX(People!$B$2:$B$7,MATCH(S24,People!$A$2:$A$7,0)),"Unknown")) | M24: =IF(T24="","",IFERROR(INDEX(Recurrings!$B$2:$B$3,MATCH(T24,Recurrings!$A$2:$A$3,0)),"Unknown")) | N24: =IF(U24="","",IFERROR(INDEX(Users!$B$2:$B$2,MATCH(U24,Users!$A$2:$A$2,0)),"Unknown")) | O24: 18110823-8fe5-4547-b1d3-8dbd2cc5b2e3 | P24: 892419eb-083b-410f-b146-1f3c70914aa1 | S24: ca7539c0-14da-430a-ae59-44fee8b96222 | U24: 814248de-0f8d-4712-bd00-91d12164a414
A25: 26 | B25: Cashback | C25: 500 | D25: Income | E25: 2026-07-01T15:39:25.000 | F25: 2026-07-05T15:39:47.888 | H25: =IF(O25="","",IFERROR(INDEX(Accounts!$B$2:$B$24,MATCH(O25,Accounts!$A$2:$A$24,0)),"Unknown")) | I25: =IF(P25="","",IFERROR(INDEX(Categories!$B$2:$B$25,MATCH(P25,Categories!$A$2:$A$25,0)),"Unknown")) | J25: =IF(Q25="","",IFERROR(INDEX(Accounts!$B$2:$B$24,MATCH(Q25,Accounts!$A$2:$A$24,0)),"Unknown")) | K25: =IF(R25="","",IFERROR(INDEX(Accounts!$B$2:$B$24,MATCH(R25,Accounts!$A$2:$A$24,0)),"Unknown")) | L25: =IF(S25="","",IFERROR(INDEX(People!$B$2:$B$7,MATCH(S25,People!$A$2:$A$7,0)),"Unknown")) | M25: =IF(T25="","",IFERROR(INDEX(Recurrings!$B$2:$B$3,MATCH(T25,Recurrings!$A$2:$A$3,0)),"Unknown")) | N25: =IF(U25="","",IFERROR(INDEX(Users!$B$2:$B$2,MATCH(U25,Users!$A$2:$A$2,0)),"Unknown")) | O25: 855f5acb-cf90-4eed-bef4-7733fec688b6 | P25: 1c612037-9067-4e69-aebc-14619b77b363 | U25: 814248de-0f8d-4712-bd00-91d12164a414
A26: 27 | B26: Swiggy tandoori wings | C26: 140 | D26: Expense | E26: 2026-07-04T15:39:53.000 | F26: 2026-07-05T15:40:18.551 | H26: =IF(O26="","",IFERROR(INDEX(Accounts!$B$2:$B$24,MATCH(O26,Accounts!$A$2:$A$24,0)),"Unknown")) | I26: =IF(P26="","",IFERROR(INDEX(Categories!$B$2:$B$25,MATCH(P26,Categories!$A$2:$A$25,0)),"Unknown")) | J26: =IF(Q26="","",IFERROR(INDEX(Accounts!$B$2:$B$24,MATCH(Q26,Accounts!$A$2:$A$24,0)),"Unknown")) | K26: =IF(R26="","",IFERROR(INDEX(Accounts!$B$2:$B$24,MATCH(R26,Accounts!$A$2:$A$24,0)),"Unknown")) | L26: =IF(S26="","",IFERROR(INDEX(People!$B$2:$B$7,MATCH(S26,People!$A$2:$A$7,0)),"Unknown")) | M26: =IF(T26="","",IFERROR(INDEX(Recurrings!$B$2:$B$3,MATCH(T26,Recurrings!$A$2:$A$3,0)),"Unknown")) | N26: =IF(U26="","",IFERROR(INDEX(Users!$B$2:$B$2,MATCH(U26,Users!$A$2:$A$2,0)),"Unknown")) | O26: 855f5acb-cf90-4eed-bef4-7733fec688b6 | P26: 9ea0a2b1-4b22-40a4-81ab-843452f9c274 | U26: 814248de-0f8d-4712-bd00-91d12164a414
A27: 28 | B27: Reward redemption charges | C27: 116.82 | D27: Expense | E27: 2026-07-03T15:40:39.000 | F27: 2026-07-06T17:25:42.376 | H27: =IF(O27="","",IFERROR(INDEX(Accounts!$B$2:$B$24,MATCH(O27,Accounts!$A$2:$A$24,0)),"Unknown")) | I27: =IF(P27="","",IFERROR(INDEX(Categories!$B$2:$B$25,MATCH(P27,Categories!$A$2:$A$25,0)),"Unknown")) | J27: =IF(Q27="","",IFERROR(INDEX(Accounts!$B$2:$B$24,MATCH(Q27,Accounts!$A$2:$A$24,0)),"Unknown")) | K27: =IF(R27="","",IFERROR(INDEX(Accounts!$B$2:$B$24,MATCH(R27,Accounts!$A$2:$A$24,0)),"Unknown")) | L27: =IF(S27="","",IFERROR(INDEX(People!$B$2:$B$7,MATCH(S27,People!$A$2:$A$7,0)),"Unknown")) | M27: =IF(T27="","",IFERROR(INDEX(Recurrings!$B$2:$B$3,MATCH(T27,Recurrings!$A$2:$A$3,0)),"Unknown")) | N27: =IF(U27="","",IFERROR(INDEX(Users!$B$2:$B$2,MATCH(U27,Users!$A$2:$A$2,0)),"Unknown")) | O27: b97245b7-cfde-4557-9035-8297edba21af | P27: 892419eb-083b-410f-b146-1f3c70914aa1 | U27: 814248de-0f8d-4712-bd00-91d12164a414
A28: 29 | B28: Cc credit | C28: 34479 | D28: Expense | E28: 2026-07-05T15:56:16.942 | F28: 2026-07-05T15:56:16.942 | H28: =IF(O28="","",IFERROR(INDEX(Accounts!$B$2:$B$24,MATCH(O28,Accounts!$A$2:$A$24,0)),"Unknown")) | I28: =IF(P28="","",IFERROR(INDEX(Categories!$B$2:$B$25,MATCH(P28,Categories!$A$2:$A$25,0)),"Unknown")) | J28: =IF(Q28="","",IFERROR(INDEX(Accounts!$B$2:$B$24,MATCH(Q28,Accounts!$A$2:$A$24,0)),"Unknown")) | K28: =IF(R28="","",IFERROR(INDEX(Accounts!$B$2:$B$24,MATCH(R28,Accounts!$A$2:$A$24,0)),"Unknown")) | L28: =IF(S28="","",IFERROR(INDEX(People!$B$2:$B$7,MATCH(S28,People!$A$2:$A$7,0)),"Unknown")) | M28: =IF(T28="","",IFERROR(INDEX(Recurrings!$B$2:$B$3,MATCH(T28,Recurrings!$A$2:$A$3,0)),"Unknown")) | N28: =IF(U28="","",IFERROR(INDEX(Users!$B$2:$B$2,MATCH(U28,Users!$A$2:$A$2,0)),"Unknown")) | O28: aa69aba3-4e60-426d-adfa-15f984249883 | P28: 892419eb-083b-410f-b146-1f3c70914aa1 | U28: 814248de-0f8d-4712-bd00-91d12164a414
A29: 30 | B29: Milk eggs dahi | C29: 106 | D29: Expense | E29: 2026-07-05T20:12:18.684 | F29: 2026-07-05T20:12:18.684 | H29: =IF(O29="","",IFERROR(INDEX(Accounts!$B$2:$B$24,MATCH(O29,Accounts!$A$2:$A$24,0)),"Unknown")) | I29: =IF(P29="","",IFERROR(INDEX(Categories!$B$2:$B$25,MATCH(P29,Categories!$A$2:$A$25,0)),"Unknown")) | J29: =IF(Q29="","",IFERROR(INDEX(Accounts!$B$2:$B$24,MATCH(Q29,Accounts!$A$2:$A$24,0)),"Unknown")) | K29: =IF(R29="","",IFERROR(INDEX(Accounts!$B$2:$B$24,MATCH(R29,Accounts!$A$2:$A$24,0)),"Unknown")) | L29: =IF(S29="","",IFERROR(INDEX(People!$B$2:$B$7,MATCH(S29,People!$A$2:$A$7,0)),"Unknown")) | M29: =IF(T29="","",IFERROR(INDEX(Recurrings!$B$2:$B$3,MATCH(T29,Recurrings!$A$2:$A$3,0)),"Unknown")) | N29: =IF(U29="","",IFERROR(INDEX(Users!$B$2:$B$2,MATCH(U29,Users!$A$2:$A$2,0)),"Unknown")) | O29: aa69aba3-4e60-426d-adfa-15f984249883 | P29: 066d9d96-53ec-4eb7-a045-fc8dfb1d33cb | U29: 814248de-0f8d-4712-bd00-91d12164a414
A30: 31 | B30: Fruits | C30: 57 | D30: Expense | E30: 2026-07-05T20:12:32.035 | F30: 2026-07-05T20:12:32.035 | H30: =IF(O30="","",IFERROR(INDEX(Accounts!$B$2:$B$24,MATCH(O30,Accounts!$A$2:$A$24,0)),"Unknown")) | I30: =IF(P30="","",IFERROR(INDEX(Categories!$B$2:$B$25,MATCH(P30,Categories!$A$2:$A$25,0)),"Unknown")) | J30: =IF(Q30="","",IFERROR(INDEX(Accounts!$B$2:$B$24,MATCH(Q30,Accounts!$A$2:$A$24,0)),"Unknown")) | K30: =IF(R30="","",IFERROR(INDEX(Accounts!$B$2:$B$24,MATCH(R30,Accounts!$A$2:$A$24,0)),"Unknown")) | L30: =IF(S30="","",IFERROR(INDEX(People!$B$2:$B$7,MATCH(S30,People!$A$2:$A$7,0)),"Unknown")) | M30: =IF(T30="","",IFERROR(INDEX(Recurrings!$B$2:$B$3,MATCH(T30,Recurrings!$A$2:$A$3,0)),"Unknown")) | N30: =IF(U30="","",IFERROR(INDEX(Users!$B$2:$B$2,MATCH(U30,Users!$A$2:$A$2,0)),"Unknown")) | O30: 4b9fa03c-eddf-42ff-8d5f-eaa9e3086ce0 | P30: 9ea0a2b1-4b22-40a4-81ab-843452f9c274 | U30: 814248de-0f8d-4712-bd00-91d12164a414
A31: 32 | B31: Expense | C31: 560 | D31: Expense | E31: 2026-07-05T20:13:03.527 | F31: 2026-07-26T02:48:35.731 | H31: =IF(O31="","",IFERROR(INDEX(Accounts!$B$2:$B$24,MATCH(O31,Accounts!$A$2:$A$24,0)),"Unknown")) | I31: =IF(P31="","",IFERROR(INDEX(Categories!$B$2:$B$25,MATCH(P31,Categories!$A$2:$A$25,0)),"Unknown")) | J31: =IF(Q31="","",IFERROR(INDEX(Accounts!$B$2:$B$24,MATCH(Q31,Accounts!$A$2:$A$24,0)),"Unknown")) | K31: =IF(R31="","",IFERROR(INDEX(Accounts!$B$2:$B$24,MATCH(R31,Accounts!$A$2:$A$24,0)),"Unknown")) | L31: =IF(S31="","",IFERROR(INDEX(People!$B$2:$B$7,MATCH(S31,People!$A$2:$A$7,0)),"Unknown")) | M31: =IF(T31="","",IFERROR(INDEX(Recurrings!$B$2:$B$3,MATCH(T31,Recurrings!$A$2:$A$3,0)),"Unknown")) | N31: =IF(U31="","",IFERROR(INDEX(Users!$B$2:$B$2,MATCH(U31,Users!$A$2:$A$2,0)),"Unknown")) | O31: 8cedd8c1-7bcb-4b94-be6b-e72b888f1084 | P31: 066d9d96-53ec-4eb7-a045-fc8dfb1d33cb | S31: 7214a9a0-5619-49f8-8521-181d4faf1190 | U31: 814248de-0f8d-4712-bd00-91d12164a414
A32: 33 | B32: Expense | C32: 236 | D32: Expense | E32: 2026-07-05T23:44:26.945 | F32: 2026-07-26T02:47:31.060 | H32: =IF(O32="","",IFERROR(INDEX(Accounts!$B$2:$B$24,MATCH(O32,Accounts!$A$2:$A$24,0)),"Unknown")) | I32: =IF(P32="","",IFERROR(INDEX(Categories!$B$2:$B$25,MATCH(P32,Categories!$A$2:$A$25,0)),"Unknown")) | J32: =IF(Q32="","",IFERROR(INDEX(Accounts!$B$2:$B$24,MATCH(Q32,Accounts!$A$2:$A$24,0)),"Unknown")) | K32: =IF(R32="","",IFERROR(INDEX(Accounts!$B$2:$B$24,MATCH(R32,Accounts!$A$2:$A$24,0)),"Unknown")) | L32: =IF(S32="","",IFERROR(INDEX(People!$B$2:$B$7,MATCH(S32,People!$A$2:$A$7,0)),"Unknown")) | M32: =IF(T32="","",IFERROR(INDEX(Recurrings!$B$2:$B$3,MATCH(T32,Recurrings!$A$2:$A$3,0)),"Unknown")) | N32: =IF(U32="","",IFERROR(INDEX(Users!$B$2:$B$2,MATCH(U32,Users!$A$2:$A$2,0)),"Unknown")) | O32: 18110823-8fe5-4547-b1d3-8dbd2cc5b2e3 | P32: 892419eb-083b-410f-b146-1f3c70914aa1 | S32: ca7539c0-14da-430a-ae59-44fee8b96222 | U32: 814248de-0f8d-4712-bd00-91d12164a414
A33: 34 | B33: Shubham ko diya | C33: 100 | D33: Expense | E33: 2026-07-05T00:28:40.000 | F33: 2026-07-06T00:29:10.441 | H33: =IF(O33="","",IFERROR(INDEX(Accounts!$B$2:$B$24,MATCH(O33,Accounts!$A$2:$A$24,0)),"Unknown")) | I33: =IF(P33="","",IFERROR(INDEX(Categories!$B$2:$B$25,MATCH(P33,Categories!$A$2:$A$25,0)),"Unknown")) | J33: =IF(Q33="","",IFERROR(INDEX(Accounts!$B$2:$B$24,MATCH(Q33,Accounts!$A$2:$A$24,0)),"Unknown")) | K33: =IF(R33="","",IFERROR(INDEX(Accounts!$B$2:$B$24,MATCH(R33,Accounts!$A$2:$A$24,0)),"Unknown")) | L33: =IF(S33="","",IFERROR(INDEX(People!$B$2:$B$7,MATCH(S33,People!$A$2:$A$7,0)),"Unknown")) | M33: =IF(T33="","",IFERROR(INDEX(Recurrings!$B$2:$B$3,MATCH(T33,Recurrings!$A$2:$A$3,0)),"Unknown")) | N33: =IF(U33="","",IFERROR(INDEX(Users!$B$2:$B$2,MATCH(U33,Users!$A$2:$A$2,0)),"Unknown")) | O33: a5b44f57-40f5-4b0e-96db-1179f20d75d0 | P33: b5eb22d9-3779-43fc-99af-eded3ff9bcd8 | U33: 814248de-0f8d-4712-bd00-91d12164a414
A34: 35 | B34: Lunch | C34: 65 | D34: Expense | E34: 2026-07-06T13:39:17.797 | F34: 2026-07-06T13:39:17.797 | H34: =IF(O34="","",IFERROR(INDEX(Accounts!$B$2:$B$24,MATCH(O34,Accounts!$A$2:$A$24,0)),"Unknown")) | I34: =IF(P34="","",IFERROR(INDEX(Categories!$B$2:$B$25,MATCH(P34,Categories!$A$2:$A$25,0)),"Unknown")) | J34: =IF(Q34="","",IFERROR(INDEX(Accounts!$B$2:$B$24,MATCH(Q34,Accounts!$A$2:$A$24,0)),"Unknown")) | K34: =IF(R34="","",IFERROR(INDEX(Accounts!$B$2:$B$24,MATCH(R34,Accounts!$A$2:$A$24,0)),"Unknown")) | L34: =IF(S34="","",IFERROR(INDEX(People!$B$2:$B$7,MATCH(S34,People!$A$2:$A$7,0)),"Unknown")) | M34: =IF(T34="","",IFERROR(INDEX(Recurrings!$B$2:$B$3,MATCH(T34,Recurrings!$A$2:$A$3,0)),"Unknown")) | N34: =IF(U34="","",IFERROR(INDEX(Users!$B$2:$B$2,MATCH(U34,Users!$A$2:$A$2,0)),"Unknown")) | O34: a5b44f57-40f5-4b0e-96db-1179f20d75d0 | P34: 9ea0a2b1-4b22-40a4-81ab-843452f9c274 | U34: 814248de-0f8d-4712-bd00-91d12164a414
A35: 36 | B35: Amazon shopping | C35: 3470 | D35: Expense | E35: 2026-07-06T17:25:08.579 | F35: 2026-07-06T17:25:08.579 | G35: Dipen and mom | H35: =IF(O35="","",IFERROR(INDEX(Accounts!$B$2:$B$24,MATCH(O35,Accounts!$A$2:$A$24,0)),"Unknown")) | I35: =IF(P35="","",IFERROR(INDEX(Categories!$B$2:$B$25,MATCH(P35,Categories!$A$2:$A$25,0)),"Unknown")) | J35: =IF(Q35="","",IFERROR(INDEX(Accounts!$B$2:$B$24,MATCH(Q35,Accounts!$A$2:$A$24,0)),"Unknown")) | K35: =IF(R35="","",IFERROR(INDEX(Accounts!$B$2:$B$24,MATCH(R35,Accounts!$A$2:$A$24,0)),"Unknown")) | L35: =IF(S35="","",IFERROR(INDEX(People!$B$2:$B$7,MATCH(S35,People!$A$2:$A$7,0)),"Unknown")) | M35: =IF(T35="","",IFERROR(INDEX(Recurrings!$B$2:$B$3,MATCH(T35,Recurrings!$A$2:$A$3,0)),"Unknown")) | N35: =IF(U35="","",IFERROR(INDEX(Users!$B$2:$B$2,MATCH(U35,Users!$A$2:$A$2,0)),"Unknown")) | O35: b97245b7-cfde-4557-9035-8297edba21af | P35: d1a09f78-95d2-4fb3-9dd1-1ae8a33fa3d8 | U35: 814248de-0f8d-4712-bd00-91d12164a414
A36: 37 | B36: Office Transport Leverage | C36: 200 | D36: Income | E36: 2026-07-06T20:44:45.223 | F36: 2026-07-06T18:41:08.053 | H36: =IF(O36="","",IFERROR(INDEX(Accounts!$B$2:$B$24,MATCH(O36,Accounts!$A$2:$A$24,0)),"Unknown")) | I36: =IF(P36="","",IFERROR(INDEX(Categories!$B$2:$B$25,MATCH(P36,Categories!$A$2:$A$25,0)),"Unknown")) | J36: =IF(Q36="","",IFERROR(INDEX(Accounts!$B$2:$B$24,MATCH(Q36,Accounts!$A$2:$A$24,0)),"Unknown")) | K36: =IF(R36="","",IFERROR(INDEX(Accounts!$B$2:$B$24,MATCH(R36,Accounts!$A$2:$A$24,0)),"Unknown")) | L36: =IF(S36="","",IFERROR(INDEX(People!$B$2:$B$7,MATCH(S36,People!$A$2:$A$7,0)),"Unknown")) | M36: =IF(T36="","",IFERROR(INDEX(Recurrings!$B$2:$B$3,MATCH(T36,Recurrings!$A$2:$A$3,0)),"Unknown")) | N36: =IF(U36="","",IFERROR(INDEX(Users!$B$2:$B$2,MATCH(U36,Users!$A$2:$A$2,0)),"Unknown")) | O36: f89518bd-b7d1-4658-9692-994af79cfcb8 | P36: f894a6a7-dfc4-4c79-bf71-b2526dc474ac | T36: 5f717740-b341-4fec-9dee-eb1c70d3c260 | U36: 814248de-0f8d-4712-bd00-91d12164a414
A37: 38 | B37: Office fare | C37: 27 | D37: Expense | E37: 2026-07-06T19:04:56.938 | F37: 2026-07-06T19:04:56.938 | H37: =IF(O37="","",IFERROR(INDEX(Accounts!$B$2:$B$24,MATCH(O37,Accounts!$A$2:$A$24,0)),"Unknown")) | I37: =IF(P37="","",IFERROR(INDEX(Categories!$B$2:$B$25,MATCH(P37,Categories!$A$2:$A$25,0)),"Unknown")) | J37: =IF(Q37="","",IFERROR(INDEX(Accounts!$B$2:$B$24,MATCH(Q37,Accounts!$A$2:$A$24,0)),"Unknown")) | K37: =IF(R37="","",IFERROR(INDEX(Accounts!$B$2:$B$24,MATCH(R37,Accounts!$A$2:$A$24,0)),"Unknown")) | L37: =IF(S37="","",IFERROR(INDEX(People!$B$2:$B$7,MATCH(S37,People!$A$2:$A$7,0)),"Unknown")) | M37: =IF(T37="","",IFERROR(INDEX(Recurrings!$B$2:$B$3,MATCH(T37,Recurrings!$A$2:$A$3,0)),"Unknown")) | N37: =IF(U37="","",IFERROR(INDEX(Users!$B$2:$B$2,MATCH(U37,Users!$A$2:$A$2,0)),"Unknown")) | O37: 7f7a9ca8-7be5-4ea0-811a-63e598d2c6d3 | P37: 59cb1d7a-195c-4fef-b7e6-682eb97de8a7 | U37: 814248de-0f8d-4712-bd00-91d12164a414
A38: 39 | B38: Pixel 10 pro case moonstone | C38: 2244 | D38: Expense | E38: 2026-07-06T21:11:29.142 | F38: 2026-07-06T21:11:29.142 | H38: =IF(O38="","",IFERROR(INDEX(Accounts!$B$2:$B$24,MATCH(O38,Accounts!$A$2:$A$24,0)),"Unknown")) | I38: =IF(P38="","",IFERROR(INDEX(Categories!$B$2:$B$25,MATCH(P38,Categories!$A$2:$A$25,0)),"Unknown")) | J38: =IF(Q38="","",IFERROR(INDEX(Accounts!$B$2:$B$24,MATCH(Q38,Accounts!$A$2:$A$24,0)),"Unknown")) | K38: =IF(R38="","",IFERROR(INDEX(Accounts!$B$2:$B$24,MATCH(R38,Accounts!$A$2:$A$24,0)),"Unknown")) | L38: =IF(S38="","",IFERROR(INDEX(People!$B$2:$B$7,MATCH(S38,People!$A$2:$A$7,0)),"Unknown")) | M38: =IF(T38="","",IFERROR(INDEX(Recurrings!$B$2:$B$3,MATCH(T38,Recurrings!$A$2:$A$3,0)),"Unknown")) | N38: =IF(U38="","",IFERROR(INDEX(Users!$B$2:$B$2,MATCH(U38,Users!$A$2:$A$2,0)),"Unknown")) | O38: 88892af2-1b81-4798-904f-38a863b1aa57 | P38: d1a09f78-95d2-4fb3-9dd1-1ae8a33fa3d8 | U38: 814248de-0f8d-4712-bd00-91d12164a414
A39: 40 | B39: Sabji | C39: 230 | D39: Expense | E39: 2026-07-06T21:34:54.020 | F39: 2026-07-26T02:48:42.045 | H39: =IF(O39="","",IFERROR(INDEX(Accounts!$B$2:$B$24,MATCH(O39,Accounts!$A$2:$A$24,0)),"Unknown")) | I39: =IF(P39="","",IFERROR(INDEX(Categories!$B$2:$B$25,MATCH(P39,Categories!$A$2:$A$25,0)),"Unknown")) | J39: =IF(Q39="","",IFERROR(INDEX(Accounts!$B$2:$B$24,MATCH(Q39,Accounts!$A$2:$A$24,0)),"Unknown")) | K39: =IF(R39="","",IFERROR(INDEX(Accounts!$B$2:$B$24,MATCH(R39,Accounts!$A$2:$A$24,0)),"Unknown")) | L39: =IF(S39="","",IFERROR(INDEX(People!$B$2:$B$7,MATCH(S39,People!$A$2:$A$7,0)),"Unknown")) | M39: =IF(T39="","",IFERROR(INDEX(Recurrings!$B$2:$B$3,MATCH(T39,Recurrings!$A$2:$A$3,0)),"Unknown")) | N39: =IF(U39="","",IFERROR(INDEX(Users!$B$2:$B$2,MATCH(U39,Users!$A$2:$A$2,0)),"Unknown")) | O39: 8cedd8c1-7bcb-4b94-be6b-e72b888f1084 | P39: 066d9d96-53ec-4eb7-a045-fc8dfb1d33cb | S39: 7214a9a0-5619-49f8-8521-181d4faf1190 | U39: 814248de-0f8d-4712-bd00-91d12164a414
A40: 41 | B40: Water | C40: 30 | D40: Expense | E40: 2026-07-06T21:37:47.042 | F40: 2026-07-26T02:49:51.200 | H40: =IF(O40="","",IFERROR(INDEX(Accounts!$B$2:$B$24,MATCH(O40,Accounts!$A$2:$A$24,0)),"Unknown")) | I40: =IF(P40="","",IFERROR(INDEX(Categories!$B$2:$B$25,MATCH(P40,Categories!$A$2:$A$25,0)),"Unknown")) | J40: =IF(Q40="","",IFERROR(INDEX(Accounts!$B$2:$B$24,MATCH(Q40,Accounts!$A$2:$A$24,0)),"Unknown")) | K40: =IF(R40="","",IFERROR(INDEX(Accounts!$B$2:$B$24,MATCH(R40,Accounts!$A$2:$A$24,0)),"Unknown")) | L40: =IF(S40="","",IFERROR(INDEX(People!$B$2:$B$7,MATCH(S40,People!$A$2:$A$7,0)),"Unknown")) | M40: =IF(T40="","",IFERROR(INDEX(Recurrings!$B$2:$B$3,MATCH(T40,Recurrings!$A$2:$A$3,0)),"Unknown")) | N40: =IF(U40="","",IFERROR(INDEX(Users!$B$2:$B$2,MATCH(U40,Users!$A$2:$A$2,0)),"Unknown")) | O40: 183283c7-9ae3-49e4-ae84-a5364bc337ea | P40: b5eb22d9-3779-43fc-99af-eded3ff9bcd8 | S40: 7214a9a0-5619-49f8-8521-181d4faf1190 | U40: 814248de-0f8d-4712-bd00-91d12164a414
...

Sheet Accounts
A1: UUID | B1: Account Name | C1: Bank Name | D1: Account Type | E1: Currency Code | F1: Balance | G1: Is Default | H1: Is Excluded
A2: a5b44f57-40f5-4b0e-96db-1179f20d75d0 | B2: Axis Bank Salary Gautam Saha | C2: Gautam Axis Bank | D2: Cash | F2: 0 | G2: No | H2: No
A3: 7f7a9ca8-7be5-4ea0-811a-63e598d2c6d3 | B3: Gautam Cash | C3: Cash | D3: Card | F3: 0 | G3: No | H3: No
A4: 183283c7-9ae3-49e4-ae84-a5364bc337ea | B4: Dipali Saha Bandhan Bank SB | C4: Bandhan Bank Dipali | D4: Bank Account | F4: 30000 | G4: No | H4: No
A5: e4446497-b2a1-4493-a796-44893af13f78 | B5: Dipen Chandra Saha Bandhan Bank SB | C5: Bandhan Bank Dipen | D5: Bank Account | F5: 0 | G5: No | H5: No
A6: 07510728-f320-4be7-b92d-39526c02e73d | B6: Gautam Chandra Saha Bandhan Bank SB | C6: Bandhan Bank Gautam | D6: Bank Account | F6: 0 | G6: No | H6: No
A7: 6b8aeda1-8500-4f9c-996c-55ad6f6d1bf3 | B7: Dipali Devi Saha Elite | C7: Bandhan Bank Elite | D7: Bank Account | F7: 12874421 | G7: No | H7: No
A8: 641abbfc-3036-49d3-9ffa-8dfcf749f46e | B8: All Accounts Bandhan Bank | C8: Bandhan Bank | D8: Bank Account | F8: 0 | G8: No | H8: No
A9: 18110823-8fe5-4547-b1d3-8dbd2cc5b2e3 | B9: State Bank Of India Dipen | C9: State Bank Of India Dipen | D9: Bank Account | F9: 0 | G9: No | H9: No
A10: 8cedd8c1-7bcb-4b94-be6b-e72b888f1084 | B10: Daily Ghar Kharcha Cash | C10: Cash Home | D10: Card | F10: 0 | G10: No | H10: No
A11: 2b9af0c9-8855-4666-9be1-4c781d9f1ec3 | B11: IDFC bank Gautam | C11: IDFC bank Gautam | D11: Bank Account | F11: 0 | G11: No | H11: No
A12: 4b9fa03c-eddf-42ff-8d5f-eaa9e3086ce0 | B12: Union Bank Gautam | C12: Union Bank Gautam | D12: Bank Account | F12: 11147 | G12: No | H12: No
A13: f89518bd-b7d1-4658-9692-994af79cfcb8 | B13: Office Transport Perks | C13: Office Transport Perk | D13: Card | F13: 0 | G13: No | H13: No
... A24: 79affae5-0d49-47c0-887f-c87bff8f886e | B24: Dumping Account For Recon | C24: Dump Account | D24: Bank Account | F24: 0 | G24: No | H24: No

Sheet Categories
A1: UUID | B1: Category Name | C1: Category Kind | D1: Description
A2: 650e8aa0-fa64-4d3b-8aea-4a5a8cda0750 | B2: Salary | C2: Income
A3: f894a6a7-dfc4-4c79-bf71-b2526dc474ac | B3: Business | C3: Income
A4: f3c3e6df-f387-4860-b6dd-067f4574003c | B4: Gifts | C4: Income
A5: 1593bae6-402a-4f21-b61b-ced2466e51f3 | B5: Investments | C5: Income
A6: 1c612037-9067-4e69-aebc-14619b77b363 | B6: Savings | C6: Income
A7: 892419eb-083b-410f-b146-1f3c70914aa1 | B7: Bills | C7: Expense
A8: 918ebcda-33fa-40b6-848d-95dd00f74bad | B8: Rent | C8: Expense
A9: b2894a89-04c7-4991-af5f-589debb52e30 | B9: Travel | C9: Expense
A10: 9ea0a2b1-4b22-40a4-81ab-843452f9c274 | B10: Food | C10: Expense
A11: 59cb1d7a-195c-4fef-b7e6-682eb97de8a7 | B11: Transport | C11: Expense
A12: d1a09f78-95d2-4fb3-9dd1-1ae8a33fa3d8 | B12: Shopping | C12: Expense
A13: 3ae7db0e-10d1-4fd7-b789-3ec1930fa321 | B13: Entertainment | C13: Expense
... A25: e437a0b5-5f69-4f5b-b879-b8de520215cc | B25: Perk | C25: Income

Sheet People
A1: UUID | B1: Person Name | C1: Description
A2: 7214a9a0-5619-49f8-8521-181d4faf1190 | B2: Dipali
A3: ca7539c0-14da-430a-ae59-44fee8b96222 | B3: Dipen
A4: a86797b7-3cdf-415f-b4ea-16b33ec6d09d | B4: avijitm
A5: e4d7649a-60df-4f0e-a26f-923f8c156122 | B5: nakuln
A6: c2924423-e15e-4e4a-991e-22ad8a4994d2 | B6: jagadiss
A7: 8dae8d46-a8ba-4bb7-af66-0b6bf785eb6f | B7: Gautam

Sheet Users
A1: UUID | B1: User Name | C1: Currency
A2: 814248de-0f8d-4712-bd00-91d12164a414 | B2: Gautam | C2: INR

Sheet Recurrings
A1: UUID | B1: Recurring Name | C1: Period
A2: c893b300-6371-4ec2-b676-904a53f5443f | B2: Spotify premium | C2: 3
A3: 5f717740-b341-4fec-9dee-eb1c70d3c260 | B3: Office Transport Leverage | C3: 0
